Workbook

Sheet Search
B1: CONSOLIDATED SUPPLIER PRICE LIST - SEARCH
B2: Pick from the yellow dropdowns (or type a keyword). Leave a box blank or 'All' to ignore it. Item list follows the chosen Category.
B4: Supplier | C4: All | G4: Matches found: | H4: ='Price List'!M1352 -> 1351
B5: Category | C5: All | G5: Showing up to: | H5: 400
B6: Item / Brand | C6: All | G6: Total items in list: | H6: =COUNTA('Price List'!A2:A1352) -> 1351
B7: Keyword (any text) | G7: Example: Keyword 'Conqueror', Size '25 x 38'
B8: Size contains
A10: # | B10: Supplier | C10: Category | D10: Item / Brand | E10: Description / Color | F10: GSM / Caliper / Code | G10: Size | H10: Unit / Packing | I10: Price (PHP) | J10: Notes | K10: Price List Date | L10: row
A11: 1 | B11: =IF($L11="","",INDEX('Price List'!$B$2:$B$1352,$L11)&"") -> Hi-Gloss Lamination, Inc. | C11: =IF($L11="","",INDEX('Price List'!$C$2:$C$1352,$L11)&"") -> Lamination / Finishing Service | D11: =IF($L11="","",INDEX('Price List'!$D$2:$D$1352,$L11)&"") -> 5D Spot Hologram (3 Designs) | E11: =IF($L11="","",INDEX('Price List'!$E$2:$E$1352,$L11)&"") | F11: =IF($L11="","",INDEX('Price List'!$F$2:$F$1352,$L11)&"") | G11: =IF($L11="","",INDEX('Price List'!$G$2:$G$1352,$L11)&"") | H11: =IF($L11="","",INDEX('Price List'!$H$2:$H$1352,$L11)&"") -> per sq. inch | I11: =IF($L11="","",IF(INDEX('Price List'!$I$2:$I$1352,$L11)="","",INDEX('Price List'!$I$2:$I$1352,$L11))) -> 0.018 | J11: =IF($L11="","",INDEX('Price List'!$J$2:$J$1352,$L11)&"") -> Min. P2.00/sheet; Min. P1,500.00/job | K11: =IF($L11="","",INDEX('Price List'!$K$2:$K$1352,$L11)&"") -> Sep 2018 | L11: =IF(1>$H$4,"",MATCH(1,'Price List'!$M$2:$M$1352,0)) -> 1
A12: 2 | B12: =IF($L12="","",INDEX('Price List'!$B$2:$B$1352,$L12)&"") -> Hi-Gloss Lamination, Inc. | C12: =IF($L12="","",INDEX('Price List'!$C$2:$C$1352,$L12)&"") -> Lamination / Finishing Service | D12: =IF($L12="","",INDEX('Price List'!$D$2:$D$1352,$L12)&"") -> 3D Dyna Spot (Pattern) | E12: =IF($L12="","",INDEX('Price List'!$E$2:$E$1352,$L12)&"") | F12: =IF($L12="","",INDEX('Price List'!$F$2:$F$1352,$L12)&"") | G12: =IF($L12="","",INDEX('Price List'!$G$2:$G$1352,$L12)&"") | H12: =IF($L12="","",INDEX('Price List'!$H$2:$H$1352,$L12)&"") -> per sq. inch | I12: =IF($L12="","",IF(INDEX('Price List'!$I$2:$I$1352,$L12)="","",INDEX('Price List'!$I$2:$I$1352,$L12))) -> 0.008 | J12: =IF($L12="","",INDEX('Price List'!$J$2:$J$1352,$L12)&"") -> Min. P1.00/sheet; Min. P1,000.00/job | K12: =IF($L12="","",INDEX('Price List'!$K$2:$K$1352,$L12)&"") -> Sep 2018 | L12: =IF(2>$H$4,"",MATCH(2,'Price List'!$M$2:$M$1352,0)) -> 2
A13: 3 | B13: =IF($L13="","",INDEX('Price List'!$B$2:$B$1352,$L13)&"") -> Hi-Gloss Lamination, Inc. | C13: =IF($L13="","",INDEX('Price List'!$C$2:$C$1352,$L13)&"") -> Lamination / Finishing Service | D13: =IF($L13="","",INDEX('Price List'!$D$2:$D$1352,$L13)&"") -> 3D Spot (Ordinary / Semi-Heavy Duty) | E13: =IF($L13="","",INDEX('Price List'!$E$2:$E$1352,$L13)&"") | F13: =IF($L13="","",INDEX('Price List'!$F$2:$F$1352,$L13)&"") | G13: =IF($L13="","",INDEX('Price List'!$G$2:$G$1352,$L13)&"") | H13: =IF($L13="","",INDEX('Price List'!$H$2:$H$1352,$L13)&"") -> per sq. inch | I13: =IF($L13="","",IF(INDEX('Price List'!$I$2:$I$1352,$L13)="","",INDEX('Price List'!$I$2:$I$1352,$L13))) -> 0.006 | J13: =IF($L13="","",INDEX('Price List'!$J$2:$J$1352,$L13)&"") -> Min. P1.00/sheet; Min. P1,000.00/job | K13: =IF($L13="","",INDEX('Price List'!$K$2:$K$1352,$L13)&"") -> Sep 2018 | L13: =IF(3>$H$4,"",MATCH(3,'Price List'!$M$2:$M$1352,0)) -> 3
A14: 4 | B14: =IF($L14="","",INDEX('Price List'!$B$2:$B$1352,$L14)&"") -> Hi-Gloss Lamination, Inc. | C14: =IF($L14="","",INDEX('Price List'!$C$2:$C$1352,$L14)&"") -> Lamination / Finishing Service | D14: =IF($L14="","",INDEX('Price List'!$D$2:$D$1352,$L14)&"") -> 3D Spot (Heavy Duty) | E14: =IF($L14="","",INDEX('Price List'!$E$2:$E$1352,$L14)&"") | F14: =IF($L14="","",INDEX('Price List'!$F$2:$F$1352,$L14)&"") | G14: =IF($L14="","",INDEX('Price List'!$G$2:$G$1352,$L14)&"") | H14: =IF($L14="","",INDEX('Price List'!$H$2:$H$1352,$L14)&"") -> per sq. inch | I14: =IF($L14="","",IF(INDEX('Price List'!$I$2:$I$1352,$L14)="","",INDEX('Price List'!$I$2:$I$1352,$L14))) -> 0.009 | J14: =IF($L14="","",INDEX('Price List'!$J$2:$J$1352,$L14)&"") -> Min. P1.00/sheet; Min. P1,000.00/job | K14: =IF($L14="","",INDEX('Price List'!$K$2:$K$1352,$L14)&"") -> Sep 2018 | L14: =IF(4>$H$4,"",MATCH(4,'Price List'!$M$2:$M$1352,0)) -> 4
A15: 5 | B15: =IF($L15="","",INDEX('Price List'!$B$2:$B$1352,$L15)&"") -> Hi-Gloss Lamination, Inc. | C15: =IF($L15="","",INDEX('Price List'!$C$2:$C$1352,$L15)&"") -> Lamination / Finishing Service | D15: =IF($L15="","",INDEX('Price List'!$D$2:$D$1352,$L15)&"") -> 3D Glitters (Multi-Colored) | E15: =IF($L15="","",INDEX('Price List'!$E$2:$E$1352,$L15)&"") | F15: =IF($L15="","",INDEX('Price List'!$F$2:$F$1352,$L15)&"") | G15: =IF($L15="","",INDEX('Price List'!$G$2:$G$1352,$L15)&"") | H15: =IF($L15="","",INDEX('Price List'!$H$2:$H$1352,$L15)&"") -> per sq. inch | I15: =IF($L15="","",IF(INDEX('Price List'!$I$2:$I$1352,$L15)="","",INDEX('Price List'!$I$2:$I$1352,$L15))) -> 0.009 | J15: =IF($L15="","",INDEX('Price List'!$J$2:$J$1352,$L15)&"") -> Min. P1.00/sheet; Min. P1,000.00/job | K15: =IF($L15="","",INDEX('Price List'!$K$2:$K$1352,$L15)&"") -> Sep 2018 | L15: =IF(5>$H$4,"",MATCH(5,'Price List'!$M$2:$M$1352,0)) -> 5
A16: 6 | B16: =IF($L16="","",INDEX('Price List'!$B$2:$B$1352,$L16)&"") -> Hi-Gloss Lamination, Inc. | C16: =IF($L16="","",INDEX('Price List'!$C$2:$C$1352,$L16)&"") -> Lamination / Finishing Service | D16: =IF($L16="","",INDEX('Price List'!$D$2:$D$1352,$L16)&"") -> 3D Spot (Matt) | E16: =IF($L16="","",INDEX('Price List'!$E$2:$E$1352,$L16)&"") | F16: =IF($L16="","",INDEX('Price List'!$F$2:$F$1352,$L16)&"") | G16: =IF($L16="","",INDEX('Price List'!$G$2:$G$1352,$L16)&"") | H16: =IF($L16="","",INDEX('Price List'!$H$2:$H$1352,$L16)&"") -> per sq. inch | I16: =IF($L16="","",IF(INDEX('Price List'!$I$2:$I$1352,$L16)="","",INDEX('Price List'!$I$2:$I$1352,$L16))) -> 0.006 | J16: =IF($L16="","",INDEX('Price List'!$J$2:$J$1352,$L16)&"") -> Min. P1.00/sheet; Min. P1,000.00/job | K16: =IF($L16="","",INDEX('Price List'!$K$2:$K$1352,$L16)&"") -> Sep 2018 | L16: =IF(6>$H$4,"",MATCH(6,'Price List'!$M$2:$M$1352,0)) -> 6
A17: 7 | B17: =IF($L17="","",INDEX('Price List'!$B$2:$B$1352,$L17)&"") -> Hi-Gloss Lamination, Inc. | C17: =IF($L17="","",INDEX('Price List'!$C$2:$C$1352,$L17)&"") -> Lamination / Finishing Service | D17: =IF($L17="","",INDEX('Price List'!$D$2:$D$1352,$L17)&"") -> 3D Stone Finish | E17: =IF($L17="","",INDEX('Price List'!$E$2:$E$1352,$L17)&"") | F17: =IF($L17="","",INDEX('Price List'!$F$2:$F$1352,$L17)&"") | G17: =IF($L17="","",INDEX('Price List'!$G$2:$G$1352,$L17)&"") | H17: =IF($L17="","",INDEX('Price List'!$H$2:$H$1352,$L17)&"") -> per sq. inch | I17: =IF($L17="","",IF(INDEX('Price List'!$I$2:$I$1352,$L17)="","",INDEX('Price List'!$I$2:$I$1352,$L17))) -> 0.009 | J17: =IF($L17="","",INDEX('Price List'!$J$2:$J$1352,$L17)&"") -> Min. P1.00/sheet; Min. P1,000.00/job | K17: =IF($L17="","",INDEX('Price List'!$K$2:$K$1352,$L17)&"") -> Sep 2018 | L17: =IF(7>$H$4,"",MATCH(7,'Price List'!$M$2:$M$1352,0)) -> 7
A18: 8 | B18: =IF($L18="","",INDEX('Price List'!$B$2:$B$1352,$L18)&"") -> Hi-Gloss Lamination, Inc. | C18: =IF($L18="","",INDEX('Price List'!$C$2:$C$1352,$L18)&"") -> Lamination / Finishing Service | D18: =IF($L18="","",INDEX('Price List'!$D$2:$D$1352,$L18)&"") -> Texture Embossing | E18: =IF($L18="","",INDEX('Price List'!$E$2:$E$1352,$L18)&"") | F18: =IF($L18="","",INDEX('Price List'!$F$2:$F$1352,$L18)&"") | G18: =IF($L18="","",INDEX('Price List'!$G$2:$G$1352,$L18)&"") | H18: =IF($L18="","",INDEX('Price List'!$H$2:$H$1352,$L18)&"") -> per sq. inch | I18: =IF($L18="","",IF(INDEX('Price List'!$I$2:$I$1352,$L18)="","",INDEX('Price List'!$I$2:$I$1352,$L18))) -> 0.003 | J18: =IF($L18="","",INDEX('Price List'!$J$2:$J$1352,$L18)&"") -> Min. P0.50/sheet; Min. P500.00/job | K18: =IF($L18="","",INDEX('Price List'!$K$2:$K$1352,$L18)&"") -> Sep 2018 | L18: =IF(8>$H$4,"",MATCH(8,'Price List'!$M$2:$M$1352,0)) -> 8
A19: 9 | B19: =IF($L19="","",INDEX('Price List'!$B$2:$B$1352,$L19)&"") -> Hi-Gloss Lamination, Inc. | C19: =IF($L19="","",INDEX('Price List'!$C$2:$C$1352,$L19)&"") -> Lamination / Finishing Service | D19: =IF($L19="","",INDEX('Price List'!$D$2:$D$1352,$L19)&"") -> UV Coating (Full / Spot) | E19: =IF($L19="","",INDEX('Price List'!$E$2:$E$1352,$L19)&"") | F19: =IF($L19="","",INDEX('Price List'!$F$2:$F$1352,$L19)&"") | G19: =IF($L19="","",INDEX('Price List'!$G$2:$G$1352,$L19)&"") | H19: =IF($L19="","",INDEX('Price List'!$H$2:$H$1352,$L19)&"") -> per sq. inch | I19: =IF($L19="","",IF(INDEX('Price List'!$I$2:$I$1352,$L19)="","",INDEX('Price List'!$I$2:$I$1352,$L19))) -> 0.0025 | J19: =IF($L19="","",INDEX('Price List'!$J$2:$J$1352,$L19)&"") -> Min. P0.60/sheet; Min. P500.00/job | K19: =IF($L19="","",INDEX('Price List'!$K$2:$K$1352,$L19)&"") -> Sep 2018 | L19: =IF(9>$H$4,"",MATCH(9,'Price List'!$M$2:$M$1352,0)) -> 9
A20: 10 | B20: =IF($L20="","",INDEX('Price List'!$B$2:$B$1352,$L20)&"") -> Hi-Gloss Lamination, Inc. | C20: =IF($L20="","",INDEX('Price List'!$C$2:$C$1352,$L20)&"") -> Lamination / Finishing Service | D20: =IF($L20="","",INDEX('Price List'!$D$2:$D$1352,$L20)&"") -> Plastic Glossy Lamination | E20: =IF($L20="","",INDEX('Price List'!$E$2:$E$1352,$L20)&"") | F20: =IF($L20="","",INDEX('Price List'!$F$2:$F$1352,$L20)&"") | G20: =IF($L20="","",INDEX('Price List'!$G$2:$G$1352,$L20)&"") | H20: =IF($L20="","",INDEX('Price List'!$H$2:$H$1352,$L20)&"") -> per sq. inch | I20: =IF($L20="","",IF(INDEX('Price List'!$I$2:$I$1352,$L20)="","",INDEX('Price List'!$I$2:$I$1352,$L20))) -> 0.007 | J20: =IF($L20="","",INDEX('Price List'!$J$2:$J$1352,$L20)&"") -> Min. P0.70/sheet; Min. P900.00/job | K20: =IF($L20="","",INDEX('Price List'!$K$2:$K$1352,$L20)&"") -> Sep 2018 | L20: =IF(10>$H$4,"",MATCH(10,'Price List'!$M$2:$M$1352,0)) -> 10
A21: 11 | B21: =IF($L21="","",INDEX('Price List'!$B$2:$B$1352,$L21)&"") -> Hi-Gloss Lamination, Inc. | C21: =IF($L21="","",INDEX('Price List'!$C$2:$C$1352,$L21)&"") -> Lamination / Finishing Service | D21: =IF($L21="","",INDEX('Price List'!$D$2:$D$1352,$L21)&"") -> Window Lamination | E21: =IF($L21="","",INDEX('Price List'!$E$2:$E$1352,$L21)&"") | F21: =IF($L21="","",INDEX('Price List'!$F$2:$F$1352,$L21)&"") | G21: =IF($L21="","",INDEX('Price List'!$G$2:$G$1352,$L21)&"") | H21: =IF($L21="","",INDEX('Price List'!$H$2:$H$1352,$L21)&"") -> per sq. inch | I21: =IF($L21="","",IF(INDEX('Price List'!$I$2:$I$1352,$L21)="","",INDEX('Price List'!$I$2:$I$1352,$L21))) -> 0.009 | J21: =IF($L21="","",INDEX('Price List'!$J$2:$J$1352,$L21)&"") -> Min. P0.90/sheet; Min. P900.00/job | K21: =IF($L21="","",INDEX('Price List'!$K$2:$K$1352,$L21)&"") -> Sep 2018 | L21: =IF(11>$H$4,"",MATCH(11,'Price List'!$M$2:$M$1352,0)) -> 11
A22: 12 | B22: =IF($L22="","",INDEX('Price List'!$B$2:$B$1352,$L22)&"") -> Hi-Gloss Lamination, Inc. | C22: =IF($L22="","",INDEX('Price List'!$C$2:$C$1352,$L22)&"") -> Lamination / Finishing Service | D22: =IF($L22="","",INDEX('Price List'!$D$2:$D$1352,$L22)&"") -> Matt Lamination | E22: =IF($L22="","",INDEX('Price List'!$E$2:$E$1352,$L22)&"") | F22: =IF($L22="","",INDEX('Price List'!$F$2:$F$1352,$L22)&"") | G22: =IF($L22="","",INDEX('Price List'!$G$2:$G$1352,$L22)&"") | H22: =IF($L22="","",INDEX('Price List'!$H$2:$H$1352,$L22)&"") -> per sq. inch | I22: =IF($L22="","",IF(INDEX('Price List'!$I$2:$I$1352,$L22)="","",INDEX('Price List'!$I$2:$I$1352,$L22))) -> 0.007 | J22: =IF($L22="","",INDEX('Price List'!$J$2:$J$1352,$L22)&"") -> Min. P0.70/sheet; Min. P900.00/job | K22: =IF($L22="","",INDEX('Price List'!$K$2:$K$1352,$L22)&"") -> Sep 2018 | L22: =IF(12>$H$4,"",MATCH(12,'Price List'!$M$2:$M$1352,0)) -> 12
A23: 13 | B23: =IF($L23="","",INDEX('Price List'!$B$2:$B$1352,$L23)&"") -> Hi-Gloss Lamination, Inc. | C23: =IF($L23="","",INDEX('Price List'!$C$2:$C$1352,$L23)&"") -> Lamination / Finishing Service | D23: =IF($L23="","",INDEX('Price List'!$D$2:$D$1352,$L23)&"") -> Japan Blister (2 Layers) | E23: =IF($L23="","",INDEX('Price List'!$E$2:$E$1352,$L23)&"") | F23: =IF($L23="","",INDEX('Price List'!$F$2:$F$1352,$L23)&"") | G23: =IF($L23="","",INDEX('Price List'!$G$2:$G$1352,$L23)&"") | H23: =IF($L23="","",INDEX('Price List'!$H$2:$H$1352,$L23)&"") -> per sq. inch | I23: =IF($L23="","",IF(INDEX('Price List'!$I$2:$I$1352,$L23)="","",INDEX('Price List'!$I$2:$I$1352,$L23))) -> 0.008 | J23: =IF($L23="","",INDEX('Price List'!$J$2:$J$1352,$L23)&"") -> Min. P0.80/sheet; Min. P500.00/job | K23: =IF($L23="","",INDEX('Price List'!$K$2:$K$1352,$L23)&"") -> Sep 2018 | L23: =IF(13>$H$4,"",MATCH(13,'Price List'!$M$2:$M$1352,0)) -> 13
A24: 14 | B24: =IF($L24="","",INDEX('Price List'!$B$2:$B$1352,$L24)&"") -> Hi-Gloss Lamination, Inc. | C24: =IF($L24="","",INDEX('Price List'!$C$2:$C$1352,$L24)&"") -> Lamination / Finishing Service | D24: =IF($L24="","",INDEX('Price List'!$D$2:$D$1352,$L24)&"") -> Hologram Lamination | E24: =IF($L24="","",INDEX('Price List'!$E$2:$E$1352,$L24)&"") | F24: =IF($L24="","",INDEX('Price List'!$F$2:$F$1352,$L24)&"") | G24: =IF($L24="","",INDEX('Price List'!$G$2:$G$1352,$L24)&"") -> Width 12" | H24: =IF($L24="","",INDEX('Price List'!$H$2:$H$1352,$L24)&"") -> per sq. inch | I24: =IF($L24="","",IF(INDEX('Price List'!$I$2:$I$1352,$L24)="","",INDEX('Price List'!$I$2:$I$1352,$L24))) -> 0.025 | J24: =IF($L24="","",INDEX('Price List'!$J$2:$J$1352,$L24)&"") -> Min. P2.00/sheet; Min. P1,000.00/job | K24: =IF($L24="","",INDEX('Price List'!$K$2:$K$1352,$L24)&"") -> Sep 2018 | L24: =IF(14>$H$4,"",MATCH(14,'Price List'!$M$2:$M$1352,0)) -> 14
A25: 15 | B25: =IF($L25="","",INDEX('Price List'!$B$2:$B$1352,$L25)&"") -> Hi-Gloss Lamination, Inc. | C25: =IF($L25="","",INDEX('Price List'!$C$2:$C$1352,$L25)&"") -> Lamination / Finishing Service | D25: =IF($L25="","",INDEX('Price List'!$D$2:$D$1352,$L25)&"") -> Wax Lamination | E25: =IF($L25="","",INDEX('Price List'!$E$2:$E$1352,$L25)&"") | F25: =IF($L25="","",INDEX('Price List'!$F$2:$F$1352,$L25)&"") | G25: =IF($L25="","",INDEX('Price List'!$G$2:$G$1352,$L25)&"") | H25: =IF($L25="","",INDEX('Price List'!$H$2:$H$1352,$L25)&"") -> per sq. inch | I25: =IF($L25="","",IF(INDEX('Price List'!$I$2:$I$1352,$L25)="","",INDEX('Price List'!$I$2:$I$1352,$L25))) -> 0.0035 | J25: =IF($L25="","",INDEX('Price List'!$J$2:$J$1352,$L25)&"") -> Min. P1.00/sheet; Min. P1,000.00/job | K25: =IF($L25="","",INDEX('Price List'!$K$2:$K$1352,$L25)&"") -> Sep 2018 | L25: =IF(15>$H$4,"",MATCH(15,'Price List'!$M$2:$M$1352,0)) -> 15
A26: 16 | B26: =IF($L26="","",INDEX('Price List'!$B$2:$B$1352,$L26)&"") -> Hi-Gloss Lamination, Inc. | C26: =IF($L26="","",INDEX('Price List'!$C$2:$C$1352,$L26)&"") -> Lamination / Finishing Service | D26: =IF($L26="","",INDEX('Price List'!$D$2:$D$1352,$L26)&"") -> Velvet Soft Touch | E26: =IF($L26="","",INDEX('Price List'!$E$2:$E$1352,$L26)&"") | F26: =IF($L26="","",INDEX('Price List'!$F$2:$F$1352,$L26)&"") | G26: =IF($L26="","",INDEX('Price List'!$G$2:$G$1352,$L26)&"") -> Width 12.5", 18.75", 24" | H26: =IF($L26="","",INDEX('Price List'!$H$2:$H$1352,$L26)&"") -> per sq. inch | I26: =IF($L26="","",IF(INDEX('Price List'!$I$2:$I$1352,$L26)="","",INDEX('Price List'!$I$2:$I$1352,$L26))) -> 0.035 | J26: =IF($L26="","",INDEX('Price List'!$J$2:$J$1352,$L26)&"") -> Min. P2.00/sheet; Min. P1,500.00/job | K26: =IF($L26="","",INDEX('Price List'!$K$2:$K$1352,$L26)&"") -> Sep 2018 | L26: =IF(16>$H$4,"",MATCH(16,'Price List'!$M$2:$M$1352,0)) -> 16
A27: 17 | B27: =IF($L27="","",INDEX('Price List'!$B$2:$B$1352,$L27)&"") -> Hi-Gloss Lamination, Inc. | C27: =IF($L27="","",INDEX('Price List'!$C$2:$C$1352,$L27)&"") -> Lamination / Finishing Service | D27: =IF($L27="","",INDEX('Price List'!$D$2:$D$1352,$L27)&"") -> Metallized Lamination | E27: =IF($L27="","",INDEX('Price List'!$E$2:$E$1352,$L27)&"") -> Silver | F27: =IF($L27="","",INDEX('Price List'!$F$2:$F$1352,$L27)&"") | G27: =IF($L27="","",INDEX('Price List'!$G$2:$G$1352,$L27)&"") -> Width 31" or 25" | H27: =IF($L27="","",INDEX('Price List'!$H$2:$H$1352,$L27)&"") -> per sq. inch | I27: =IF($L27="","",IF(INDEX('Price List'!$I$2:$I$1352,$L27)="","",INDEX('Price List'!$I$2:$I$1352,$L27))) -> 0.016 | J27: =IF($L27="","",INDEX('Price List'!$J$2:$J$1352,$L27)&"") -> Min. P2,000.00/job | K27: =IF($L27="","",INDEX('Price List'!$K$2:$K$1352,$L27)&"") -> Sep 2018 | L27: =IF(17>$H$4,"",MATCH(17,'Price List'!$M$2:$M$1352,0)) -> 17
A28: 18 | B28: =IF($L28="","",INDEX('Price List'!$B$2:$B$1352,$L28)&"") -> Hi-Gloss Lamination, Inc. | C28: =IF($L28="","",INDEX('Price List'!$C$2:$C$1352,$L28)&"") -> Lamination / Finishing Service | D28: =IF($L28="","",INDEX('Price List'!$D$2:$D$1352,$L28)&"") -> Metallized Lamination | E28: =IF($L28="","",INDEX('Price List'!$E$2:$E$1352,$L28)&"") -> Gold | F28: =IF($L28="","",INDEX('Price List'!$F$2:$F$1352,$L28)&"") | G28: =IF($L28="","",INDEX('Price List'!$G$2:$G$1352,$L28)&"") -> Width 31" or 25" | H28: =IF($L28="","",INDEX('Price List'!$H$2:$H$1352,$L28)&"") -> per sq. inch | I28: =IF($L28="","",IF(INDEX('Price List'!$I$2:$I$1352,$L28)="","",INDEX('Price List'!$I$2:$I$1352,$L28))) -> 0.024 | J28: =IF($L28="","",INDEX('Price List'!$J$2:$J$1352,$L28)&"") -> Min. P2,000.00/job | K28: =IF($L28="","",INDEX('Price List'!$K$2:$K$1352,$L28)&"") -> Sep 2018 | L28: =IF(18>$H$4,"",MATCH(18,'Price List'!$M$2:$M$1352,0)) -> 18
A29: 19 | B29: =IF($L29="","",INDEX('Price List'!$B$2:$B$1352,$L29)&"") -> Hi-Gloss Lamination, Inc. | C29: =IF($L29="","",INDEX('Price List'!$C$2:$C$1352,$L29)&"") -> Lamination / Finishing Service | D29: =IF($L29="","",INDEX('Price List'!$D$2:$D$1352,$L29)&"") -> Metallized Lamination | E29: =IF($L29="","",INDEX('Price List'!$E$2:$E$1352,$L29)&"") -> Red / Green | F29: =IF($L29="","",INDEX('Price List'!$F$2:$F$1352,$L29)&"") | G29: =IF($L29="","",INDEX('Price List'!$G$2:$G$1352,$L29)&"") -> Width 31" | H29: =IF($L29="","",INDEX('Price List'!$H$2:$H$1352,$L29)&"") -> per sq. inch | I29: =IF($L29="","",IF(INDEX('Price List'!$I$2:$I$1352,$L29)="","",INDEX('Price List'!$I$2:$I$1352,$L29))) -> 0.024 | J29: =IF($L29="","",INDEX('Price List'!$J$2:$J$1352,$L29)&"") -> Min. P2,000.00/job | K29: =IF($L29="","",INDEX('Price List'!$K$2:$K$1352,$L29)&"") -> Sep 2018 | L29: =IF(19>$H$4,"",MATCH(19,'Price List'!$M$2:$M$1352,0)) -> 19
A30: 20 | B30: =IF($L30="","",INDEX('Price List'!$B$2:$B$1352,$L30)&"") -> Hi-Gloss Lamination, Inc. | C30: =IF($L30="","",INDEX('Price List'!$C$2:$C$1352,$L30)&"") -> Lamination / Finishing Service | D30: =IF($L30="","",INDEX('Price List'!$D$2:$D$1352,$L30)&"") -> Spot UV Blanket Charge (glue lap/expiry date) | E30: =IF($L30="","",INDEX('Price List'!$E$2:$E$1352,$L30)&"") -> Small | F30: =IF($L30="","",INDEX('Price List'!$F$2:$F$1352,$L30)&"") | G30: =IF($L30="","",INDEX('Price List'!$G$2:$G$1352,$L30)&"") -> 23" x 28" | H30: =IF($L30="","",INDEX('Price List'!$H$2:$H$1352,$L30)&"") -> per job | I30: =IF($L30="","",IF(INDEX('Price List'!$I$2:$I$1352,$L30)="","",INDEX('Price List'!$I$2:$I$1352,$L30))) -> 1500 | J30: =IF($L30="","",INDEX('Price List'!$J$2:$J$1352,$L30)&"") | K30: =IF($L30="","",INDEX('Price List'!$K$2:$K$1352,$L30)&"") -> Sep 2018 | L30: =IF(20>$H$4,"",MATCH(20,'Price List'!$M$2:$M$1352,0)) -> 20
A31: 21 | B31: =IF($L31="","",INDEX('Price List'!$B$2:$B$1352,$L31)&"") -> Hi-Gloss Lamination, Inc. | C31: =IF($L31="","",INDEX('Price List'!$C$2:$C$1352,$L31)&"") -> Lamination / Finishing Service | D31: =IF($L31="","",INDEX('Price List'!$D$2:$D$1352,$L31)&"") -> Spot UV Blanket Charge (glue lap/expiry date) | E31: =IF($L31="","",INDEX('Price List'!$E$2:$E$1352,$L31)&"") -> Big | F31: =IF($L31="","",INDEX('Price List'!$F$2:$F$1352,$L31)&"") | G31: =IF($L31="","",INDEX('Price List'!$G$2:$G$1352,$L31)&"") -> 34" x 40" | H31: =IF($L31="","",INDEX('Price List'!$H$2:$H$1352,$L31)&"") -> per job | I31: =IF($L31="","",IF(INDEX('Price List'!$I$2:$I$1352,$L31)="","",INDEX('Price List'!$I$2:$I$1352,$L31))) -> 2000 | J31: =IF($L31="","",INDEX('Price List'!$J$2:$J$1352,$L31)&"") | K31: =IF($L31="","",INDEX('Price List'!$K$2:$K$1352,$L31)&"") -> Sep 2018 | L31: =IF(21>$H$4,"",MATCH(21,'Price List'!$M$2:$M$1352,0)) -> 21
A32: 22 | B32: =IF($L32="","",INDEX('Price List'!$B$2:$B$1352,$L32)&"") -> Hi-Gloss Lamination, Inc. | C32: =IF($L32="","",INDEX('Price List'!$C$2:$C$1352,$L32)&"") -> Lamination / Finishing Service | D32: =IF($L32="","",INDEX('Price List'!$D$2:$D$1352,$L32)&"") -> 3D Spot Exposure Charge | E32: =IF($L32="","",INDEX('Price List'!$E$2:$E$1352,$L32)&"") -> Small / medium size | F32: =IF($L32="","",INDEX('Price List'!$F$2:$F$1352,$L32)&"") | G32: =IF($L32="","",INDEX('Price List'!$G$2:$G$1352,$L32)&"") -> below 20" x 28" | H32: =IF($L32="","",INDEX('Price List'!$H$2:$H$1352,$L32)&"") -> per design | I32: =IF($L32="","",IF(INDEX('Price List'!$I$2:$I$1352,$L32)="","",INDEX('Price List'!$I$2:$I$1352,$L32))) -> 800 | J32: =IF($L32="","",INDEX('Price List'!$J$2:$J$1352,$L32)&"") -> Requires positive emulsion up film | K32: =IF($L32="","",INDEX('Price List'!$K$2:$K$1352,$L32)&"") -> Sep 2018 | L32: =IF(22>$H$4,"",MATCH(22,'Price List'!$M$2:$M$1352,0)) -> 22
A33: 23 | B33: =IF($L33="","",INDEX('Price List'!$B$2:$B$1352,$L33)&"") -> Hi-Gloss Lamination, Inc. | C33: =IF($L33="","",INDEX('Price List'!$C$2:$C$1352,$L33)&"") -> Lamination / Finishing Service | D33: =IF($L33="","",INDEX('Price List'!$D$2:$D$1352,$L33)&"") -> 3D Spot Exposure Charge | E33: =IF($L33="","",INDEX('Price List'!$E$2:$E$1352,$L33)&"") -> Large size | F33: =IF($L33="","",INDEX('Price List'!$F$2:$F$1352,$L33)&"") | G33: =IF($L33="","",INDEX('Price List'!$G$2:$G$1352,$L33)&"") -> 20" x 28" and above | H33: =IF($L33="","",INDEX('Price List'!$H$2:$H$1352,$L33)&"") -> per design | I33: =IF($L33="","",IF(INDEX('Price List'!$I$2:$I$1352,$L33)="","",INDEX('Price List'!$I$2:$I$1352,$L33))) -> 1200 | J33: =IF($L33="","",INDEX('Price List'!$J$2:$J$1352,$L33)&"") -> Requires positive emulsion up film | K33: =IF($L33="","",INDEX('Price List'!$K$2:$K$1352,$L33)&"") -> Sep 2018 | L33: =IF(23>$H$4,"",MATCH(23,'Price List'!$M$2:$M$1352,0)) -> 23
A34: 24 | B34: =IF($L34="","",INDEX('Price List'!$B$2:$B$1352,$L34)&"") -> Hi-Gloss Lamination, Inc. | C34: =IF($L34="","",INDEX('Price List'!$C$2:$C$1352,$L34)&"") -> Lamination / Finishing Service | D34: =IF($L34="","",INDEX('Price List'!$D$2:$D$1352,$L34)&"") -> 3D Spot - Digital Jobs | E34: =IF($L34="","",INDEX('Price List'!$E$2:$E$1352,$L34)&"") -> Minimum charge | F34: =IF($L34="","",INDEX('Price List'!$F$2:$F$1352,$L34)&"") | G34: =IF($L34="","",INDEX('Price List'!$G$2:$G$1352,$L34)&"") | H34: =IF($L34="","",INDEX('Price List'!$H$2:$H$1352,$L34)&"") -> per job | I34: =IF($L34="","",IF(INDEX('Price List'!$I$2:$I$1352,$L34)="","",INDEX('Price List'!$I$2:$I$1352,$L34))) -> 1500 | J34: =IF($L34="","",INDEX('Price List'!$J$2:$J$1352,$L34)&"") | K34: =IF($L34="","",INDEX('Price List'!$K$2:$K$1352,$L34)&"") -> Sep 2018 | L34: =IF(24>$H$4,"",MATCH(24,'Price List'!$M$2:$M$1352,0)) -> 24
A35: 25 | B35: =IF($L35="","",INDEX('Price List'!$B$2:$B$1352,$L35)&"") -> Commerce Asia, Inc. | C35: =IF($L35="","",INDEX('Price List'!$C$2:$C$1352,$L35)&"") -> Lamination Film | D35: =IF($L35="","",INDEX('Price List'!$D$2:$D$1352,$L35)&"") -> Thermal OPP Film (for offset) | E35: =IF($L35="","",INDEX('Price List'!$E$2:$E$1352,$L35)&"") -> Glossy/25, 58mm core | F35: =IF($L35="","",INDEX('Price List'!$F$2:$F$1352,$L35)&"") -> 23110-0305-1000-58 | G35: =IF($L35="","",INDEX('Price List'!$G$2:$G$1352,$L35)&"") -> 305mm (12 in) x 1000M | H35: =IF($L35="","",INDEX('Price List'!$H$2:$H$1352,$L35)&"") -> roll | I35: =IF($L35="","",IF(INDEX('Price List'!$I$2:$I$1352,$L35)="","",INDEX('Price List'!$I$2:$I$1352,$L35))) -> 2716 | J35: =IF($L35="","",INDEX('Price List'!$J$2:$J$1352,$L35)&"") -> SRP P4,850.00 less 44% discount | K35: =IF($L35="","",INDEX('Price List'!$K$2:$K$1352,$L35)&"") -> Jul 20, 2026 | L35: =IF(25>$H$4,"",MATCH(25,'Price List'!$M$2:$M$1352,0)) -> 25
A36: 26 | B36: =IF($L36="","",INDEX('Price List'!$B$2:$B$1352,$L36)&"") -> Commerce Asia, Inc. | C36: =IF($L36="","",INDEX('Price List'!$C$2:$C$1352,$L36)&"") -> Lamination Film | D36: =IF($L36="","",INDEX('Price List'!$D$2:$D$1352,$L36)&"") -> Thermal OPP Film (for offset) | E36: =IF($L36="","",INDEX('Price List'!$E$2:$E$1352,$L36)&"") -> Glossy/25, 58mm core | F36: =IF($L36="","",INDEX('Price List'!$F$2:$F$1352,$L36)&"") -> 23110-0320-1000-58 | G36: =IF($L36="","",INDEX('Price List'!$G$2:$G$1352,$L36)&"") -> 320mm (12.6 in) x 1000M | H36: =IF($L36="","",INDEX('Price List'!$H$2:$H$1352,$L36)&"") -> roll | I36: =IF($L36="","",IF(INDEX('Price List'!$I$2:$I$1352,$L36)="","",INDEX('Price List'!$I$2:$I$1352,$L36))) -> 2861.6 | J36: =IF($L36="","",INDEX('Price List'!$J$2:$J$1352,$L36)&"") -> SRP P5,110.00 less 44% discount | K36: =IF($L36="","",INDEX('Price List'!$K$2:$K$1352,$L36)&"") -> Jul 20, 2026 | L36: =IF(26>$H$4,"",MATCH(26,'Price List'!$M$2:$M$1352,0)) -> 26
A37: 27 | B37: =IF($L37="","",INDEX('Price List'!$B$2:$B$1352,$L37)&"") -> Commerce Asia, Inc. | C37: =IF($L37="","",INDEX('Price List'!$C$2:$C$1352,$L37)&"") -> Lamination Film | D37: =IF($L37="","",INDEX('Price List'!$D$2:$D$1352,$L37)&"") -> Thermal OPP Film (for offset) | E37: =IF($L37="","",INDEX('Price List'!$E$2:$E$1352,$L37)&"") -> Glossy/25, 58mm core | F37: =IF($L37="","",INDEX('Price List'!$F$2:$F$1352,$L37)&"") -> 23110-0330-1000-58 | G37: =IF($L37="","",INDEX('Price List'!$G$2:$G$1352,$L37)&"") -> 330mm (13 in) x 1000M | H37: =IF($L37="","",INDEX('Price List'!$H$2:$H$1352,$L37)&"") -> roll | I37: =IF($L37="","",IF(INDEX('Price List'!$I$2:$I$1352,$L37)="","",INDEX('Price List'!$I$2:$I$1352,$L37))) -> 2940 | J37: =IF($L37="","",INDEX('Price List'!$J$2:$J$1352,$L37)&"") -> SRP P5,250.00 less 44% discount | K37: =IF($L37="","",INDEX('Price List'!$K$2:$K$1352,$L37)&"") -> Jul 20, 2026 | L37: =IF(27>$H$4,"",MATCH(27,'Price List'!$M$2:$M$1352,0)) -> 27
A38: 28 | B38: =IF($L38="","",INDEX('Price List'!$B$2:$B$1352,$L38)&"") -> Commerce Asia, Inc. | C38: =IF($L38="","",INDEX('Price List'!$C$2:$C$1352,$L38)&"") -> Lamination Film | D38: =IF($L38="","",INDEX('Price List'!$D$2:$D$1352,$L38)&"") -> Thermal OPP Film (for offset) | E38: =IF($L38="","",INDEX('Price List'!$E$2:$E$1352,$L38)&"") -> Glossy/25, 58mm core | F38: =IF($L38="","",INDEX('Price List'!$F$2:$F$1352,$L38)&"") -> 23110-0360-1000-58 | G38: =IF($L38="","",INDEX('Price List'!$G$2:$G$1352,$L38)&"") -> 360mm (14.17 in) x 1000M | H38: =IF($L38="","",INDEX('Price List'!$H$2:$H$1352,$L38)&"") -> roll | I38: =IF($L38="","",IF(INDEX('Price List'!$I$2:$I$1352,$L38)="","",INDEX('Price List'!$I$2:$I$1352,$L38))) -> 3203.2 | J38: =IF($L38="","",INDEX('Price List'!$J$2:$J$1352,$L38)&"") -> SRP P5,720.00 less 44% discount | K38: =IF($L38="","",INDEX('Price List'!$K$2:$K$1352,$L38)&"") -> Jul 20, 2026 | L38: =IF(28>$H$4,"",MATCH(28,'Price List'!$M$2:$M$1352,0)) -> 28
A39: 29 | B39: =IF($L39="","",INDEX('Price List'!$B$2:$B$1352,$L39)&"") -> Commerce Asia, Inc. | C39: =IF($L39="","",INDEX('Price List'!$C$2:$C$1352,$L39)&"") -> Lamination Film | D39: =IF($L39="","",INDEX('Price List'!$D$2:$D$1352,$L39)&"") -> Thermal OPP Film (for offset) | E39: =IF($L39="","",INDEX('Price List'!$E$2:$E$1352,$L39)&"") -> Glossy/25, 58mm core | F39: =IF($L39="","",INDEX('Price List'!$F$2:$F$1352,$L39)&"") -> 23110-0385-1000-58 | G39: =IF($L39="","",INDEX('Price List'!$G$2:$G$1352,$L39)&"") -> 385mm (15.16 in) x 1000M | H39: =IF($L39="","",INDEX('Price List'!$H$2:$H$1352,$L39)&"") -> roll | I39: =IF($L39="","",IF(INDEX('Price List'!$I$2:$I$1352,$L39)="","",INDEX('Price List'!$I$2:$I$1352,$L39))) -> 3444 | J39: =IF($L39="","",INDEX('Price List'!$J$2:$J$1352,$L39)&"") -> SRP P6,150.00 less 44% discount | K39: =IF($L39="","",INDEX('Price List'!$K$2:$K$1352,$L39)&"") -> Jul 20, 2026 | L39: =IF(29>$H$4,"",MATCH(29,'Price List'!$M$2:$M$1352,0)) -> 29
A40: 30 | B40: =IF($L40="","",INDEX('Price List'!$B$2:$B$1352,$L40)&"") -> Commerce Asia, Inc. | C40: =IF($L40="","",INDEX('Price List'!$C$2:$C$1352,$L40)&"") -> Lamination Film | D40: =IF($L40="","",INDEX('Price List'!$D$2:$D$1352,$L40)&"") -> Thermal OPP Film (for offset) | E40: =IF($L40="","",INDEX('Price List'!$E$2:$E$1352,$L40)&"") -> Glossy/25, 58mm core | F40: =IF($L40="","",INDEX('Price List'!$F$2:$F$1352,$L40)&"") -> 23110-0410-1000-58 | G40: =IF($L40="","",INDEX('Price List'!$G$2:$G$1352,$L40)&"") -> 410mm (16.14 in) x 1000M | H40: =IF($L40="","",INDEX('Price List'!$H$2:$H$1352,$L40)&"") -> roll | I40: =IF($L40="","",IF(INDEX('Price List'!$I$2:$I$1352,$L40)="","",INDEX('Price List'!$I$2:$I$1352,$L40))) -> 3651.2 | J40: =IF($L40="","",INDEX('Price List'!$J$2:$J$1352,$L40)&"") -> SRP P6,520.00 less 44% discount | K40: =IF($L40="","",INDEX('Price List'!$K$2:$K$1352,$L40)&"") -> Jul 20, 2026 | L40: =IF(30>$H$4,"",MATCH(30,'Price List'!$M$2:$M$1352,0)) -> 30
A41: 31 | B41: =IF($L41="","",INDEX('Price List'!$B$2:$B$1352,$L41)&"") -> Commerce Asia, Inc. | C41: =IF($L41="","",INDEX('Price List'!$C$2:$C$1352,$L41)&"") -> Lamination Film | D41: =IF($L41="","",INDEX('Price List'!$D$2:$D$1352,$L41)&"") -> Thermal OPP Film (for offset) | E41: =IF($L41="","",INDEX('Price List'!$E$2:$E$1352,$L41)&"") -> Glossy/25, 58mm core | F41: =IF($L41="","",INDEX('Price List'!$F$2:$F$1352,$L41)&"") -> 23110-0432-1000-58 | G41: =IF($L41="","",INDEX('Price List'!$G$2:$G$1352,$L41)&"") -> 432mm (17 in) x 1000M | H41: =IF($L41="","",INDEX('Price List'!$H$2:$H$1352,$L41)&"") -> roll | I41: =IF($L41="","",IF(INDEX('Price List'!$I$2:$I$1352,$L41)="","",INDEX('Price List'!$I$2:$I$1352,$L41))) -> 3864 | J41: =IF($L41="","",INDEX('Price List'!$J$2:$J$1352,$L41)&"") -> SRP P6,900.00 less 44% discount | K41: =IF($L41="","",INDEX('Price List'!$K$2:$K$1352,$L41)&"") -> Jul 20, 2026 | L41: =IF(31>$H$4,"",MATCH(31,'Price List'!$M$2:$M$1352,0)) -> 31
A42: 32 | B42: =IF($L42="","",INDEX('Price List'!$B$2:$B$1352,$L42)&"") -> Commerce Asia, Inc. | C42: =IF($L42="","",INDEX('Price List'!$C$2:$C$1352,$L42)&"") -> Lamination Film | D42: =IF($L42="","",INDEX('Price List'!$D$2:$D$1352,$L42)&"") -> Thermal OPP Film (for offset) | E42: =IF($L42="","",INDEX('Price List'!$E$2:$E$1352,$L42)&"") -> Glossy/25, 58mm core | F42: =IF($L42="","",INDEX('Price List'!$F$2:$F$1352,$L42)&"") -> 23110-0460-1000-58 | G42: =IF($L42="","",INDEX('Price List'!$G$2:$G$1352,$L42)&"") -> 460mm (18.11 in) x 1000M | H42: =IF($L42="","",INDEX('Price List'!$H$2:$H$1352,$L42)&"") -> roll | I42: =IF($L42="","",IF(INDEX('Price List'!$I$2:$I$1352,$L42)="","",INDEX('Price List'!$I$2:$I$1352,$L42))) -> 4088 | J42: =IF($L42="","",INDEX('Price List'!$J$2:$J$1352,$L42)&"") -> SRP P7,300.00 less 44% discount | K42: =IF($L42="","",INDEX('Price List'!$K$2:$K$1352,$L42)&"") -> Jul 20, 2026 | L42: =IF(32>$H$4,"",MATCH(32,'Price List'!$M$2:$M$1352,0)) -> 32
...

Sheet Price List
A1: ID | B1: Supplier | C1: Category | D1: Item / Brand | E1: Description / Color | F1: GSM / Caliper / Code | G1: Size | H1: Unit / Packing | I1: Price (PHP) | J1: Notes | K1: Price List Date | L1: Match | M1: Match #
A2: 1 | B2: Hi-Gloss Lamination, Inc. | C2: Lamination / Finishing Service | D2: 5D Spot Hologram (3 Designs) | H2: per sq. inch | I2: 0.018 | J2: Min. P2.00/sheet; Min. P1,500.00/job | K2: Sep 2018 | L2: =IF(AND(OR(Search!$C$4="",Search!$C$4="All",B2=Search!$C$4),OR(Search!$C$5="",Search!$C$5="All",C2=Search!$C$5),OR(Search!$C$6="",Search!$C$6="All",D2=Search!$C$6),OR(Search!$C$7="",ISNUMBER(SEARCH(Search!$C$7,D2&" "&E2&" "&F2&" "&G2&" "&H2&" "&J2))),OR(Search!$C$8="",ISNUMBER(SEARCH(Search!$C$8,G2)))),1,0) -> 1 | M2: =L2 -> 1
A3: 2 | B3: Hi-Gloss Lamination, Inc. | C3: Lamination / Finishing Service | D3: 3D Dyna Spot (Pattern) | H3: per sq. inch | I3: 0.008 | J3: Min. P1.00/sheet; Min. P1,000.00/job | K3: Sep 2018 | L3: =IF(AND(OR(Search!$C$4="",Search!$C$4="All",B3=Search!$C$4),OR(Search!$C$5="",Search!$C$5="All",C3=Search!$C$5),OR(Search!$C$6="",Search!$C$6="All",D3=Search!$C$6),OR(Search!$C$7="",ISNUMBER(SEARCH(Search!$C$7,D3&" "&E3&" "&F3&" "&G3&" "&H3&" "&J3))),OR(Search!$C$8="",ISNUMBER(SEARCH(Search!$C$8,G3)))),1,0) -> 1 | M3: =M2+L3 -> 2
A4: 3 | B4: Hi-Gloss Lamination, Inc. | C4: Lamination / Finishing Service | D4: 3D Spot (Ordinary / Semi-Heavy Duty) | H4: per sq. inch | I4: 0.006 | J4: Min. P1.00/sheet; Min. P1,000.00/job | K4: Sep 2018 | L4: =IF(AND(OR(Search!$C$4="",Search!$C$4="All",B4=Search!$C$4),OR(Search!$C$5="",Search!$C$5="All",C4=Search!$C$5),OR(Search!$C$6="",Search!$C$6="All",D4=Search!$C$6),OR(Search!$C$7="",ISNUMBER(SEARCH(Search!$C$7,D4&" "&E4&" "&F4&" "&G4&" "&H4&" "&J4))),OR(Search!$C$8="",ISNUMBER(SEARCH(Search!$C$8,G4)))),1,0) -> 1 | M4: =M3+L4 -> 3
A5: 4 | B5: Hi-Gloss Lamination, Inc. | C5: Lamination / Finishing Service | D5: 3D Spot (Heavy Duty) | H5: per sq. inch | I5: 0.009 | J5: Min. P1.00/sheet; Min. P1,000.00/job | K5: Sep 2018 | L5: =IF(AND(OR(Search!$C$4="",Search!$C$4="All",B5=Search!$C$4),OR(Search!$C$5="",Search!$C$5="All",C5=Search!$C$5),OR(Search!$C$6="",Search!$C$6="All",D5=Search!$C$6),OR(Search!$C$7="",ISNUMBER(SEARCH(Search!$C$7,D5&" "&E5&" "&F5&" "&G5&" "&H5&" "&J5))),OR(Search!$C$8="",ISNUMBER(SEARCH(Search!$C$8,G5)))),1,0) -> 1 | M5: =M4+L5 -> 4
A6: 5 | B6: Hi-Gloss Lamination, Inc. | C6: Lamination / Finishing Service | D6: 3D Glitters (Multi-Colored) | H6: per sq. inch | I6: 0.009 | J6: Min. P1.00/sheet; Min. P1,000.00/job | K6: Sep 2018 | L6: =IF(AND(OR(Search!$C$4="",Search!$C$4="All",B6=Search!$C$4),OR(Search!$C$5="",Search!$C$5="All",C6=Search!$C$5),OR(Search!$C$6="",Search!$C$6="All",D6=Search!$C$6),OR(Search!$C$7="",ISNUMBER(SEARCH(Search!$C$7,D6&" "&E6&" "&F6&" "&G6&" "&H6&" "&J6))),OR(Search!$C$8="",ISNUMBER(SEARCH(Search!$C$8,G6)))),1,0) -> 1 | M6: =M5+L6 -> 5
A7: 6 | B7: Hi-Gloss Lamination, Inc. | C7: Lamination / Finishing Service | D7: 3D Spot (Matt) | H7: per sq. inch | I7: 0.006 | J7: Min. P1.00/sheet; Min. P1,000.00/job | K7: Sep 2018 | L7: =IF(AND(OR(Search!$C$4="",Search!$C$4="All",B7=Search!$C$4),OR(Search!$C$5="",Search!$C$5="All",C7=Search!$C$5),OR(Search!$C$6="",Search!$C$6="All",D7=Search!$C$6),OR(Search!$C$7="",ISNUMBER(SEARCH(Search!$C$7,D7&" "&E7&" "&F7&" "&G7&" "&H7&" "&J7))),OR(Search!$C$8="",ISNUMBER(SEARCH(Search!$C$8,G7)))),1,0) -> 1 | M7: =M6+L7 -> 6
A8: 7 | B8: Hi-Gloss Lamination, Inc. | C8: Lamination / Finishing Service | D8: 3D Stone Finish | H8: per sq. inch | I8: 0.009 | J8: Min. P1.00/sheet; Min. P1,000.00/job | K8: Sep 2018 | L8: =IF(AND(OR(Search!$C$4="",Search!$C$4="All",B8=Search!$C$4),OR(Search!$C$5="",Search!$C$5="All",C8=Search!$C$5),OR(Search!$C$6="",Search!$C$6="All",D8=Search!$C$6),OR(Search!$C$7="",ISNUMBER(SEARCH(Search!$C$7,D8&" "&E8&" "&F8&" "&G8&" "&H8&" "&J8))),OR(Search!$C$8="",ISNUMBER(SEARCH(Search!$C$8,G8)))),1,0) -> 1 | M8: =M7+L8 -> 7
A9: 8 | B9: Hi-Gloss Lamination, Inc. | C9: Lamination / Finishing Service | D9: Texture Embossing | H9: per sq. inch | I9: 0.003 | J9: Min. P0.50/sheet; Min. P500.00/job | K9: Sep 2018 | L9: =IF(AND(OR(Search!$C$4="",Search!$C$4="All",B9=Search!$C$4),OR(Search!$C$5="",Search!$C$5="All",C9=Search!$C$5),OR(Search!$C$6="",Search!$C$6="All",D9=Search!$C$6),OR(Search!$C$7="",ISNUMBER(SEARCH(Search!$C$7,D9&" "&E9&" "&F9&" "&G9&" "&H9&" "&J9))),OR(Search!$C$8="",ISNUMBER(SEARCH(Search!$C$8,G9)))),1,0) -> 1 | M9: =M8+L9 -> 8
A10: 9 | B10: Hi-Gloss Lamination, Inc. | C10: Lamination / Finishing Service | D10: UV Coating (Full / Spot) | H10: per sq. inch | I10: 0.0025 | J10: Min. P0.60/sheet; Min. P500.00/job | K10: Sep 2018 | L10: =IF(AND(OR(Search!$C$4="",Search!$C$4="All",B10=Search!$C$4),OR(Search!$C$5="",Search!$C$5="All",C10=Search!$C$5),OR(Search!$C$6="",Search!$C$6="All",D10=Search!$C$6),OR(Search!$C$7="",ISNUMBER(SEARCH(Search!$C$7,D10&" "&E10&" "&F10&" "&G10&" "&H10&" "&J10))),OR(Search!$C$8="",ISNUMBER(SEARCH(Search!$C$8,G10)))),1,0) -> 1 | M10: =M9+L10 -> 9
A11: 10 | B11: Hi-Gloss Lamination, Inc. | C11: Lamination / Finishing Service | D11: Plastic Glossy Lamination | H11: per sq. inch | I11: 0.007 | J11: Min. P0.70/sheet; Min. P900.00/job | K11: Sep 2018 | L11: =IF(AND(OR(Search!$C$4="",Search!$C$4="All",B11=Search!$C$4),OR(Search!$C$5="",Search!$C$5="All",C11=Search!$C$5),OR(Search!$C$6="",Search!$C$6="All",D11=Search!$C$6),OR(Search!$C$7="",ISNUMBER(SEARCH(Search!$C$7,D11&" "&E11&" "&F11&" "&G11&" "&H11&" "&J11))),OR(Search!$C$8="",ISNUMBER(SEARCH(Search!$C$8,G11)))),1,0) -> 1 | M11: =M10+L11 -> 10
A12: 11 | B12: Hi-Gloss Lamination, Inc. | C12: Lamination / Finishing Service | D12: Window Lamination | H12: per sq. inch | I12: 0.009 | J12: Min. P0.90/sheet; Min. P900.00/job | K12: Sep 2018 | L12: =IF(AND(OR(Search!$C$4="",Search!$C$4="All",B12=Search!$C$4),OR(Search!$C$5="",Search!$C$5="All",C12=Search!$C$5),OR(Search!$C$6="",Search!$C$6="All",D12=Search!$C$6),OR(Search!$C$7="",ISNUMBER(SEARCH(Search!$C$7,D12&" "&E12&" "&F12&" "&G12&" "&H12&" "&J12))),OR(Search!$C$8="",ISNUMBER(SEARCH(Search!$C$8,G12)))),1,0) -> 1 | M12: =M11+L12 -> 11
A13: 12 | B13: Hi-Gloss Lamination, Inc. | C13: Lamination / Finishing Service | D13: Matt Lamination | H13: per sq. inch | I13: 0.007 | J13: Min. P0.70/sheet; Min. P900.00/job | K13: Sep 2018 | L13: =IF(AND(OR(Search!$C$4="",Search!$C$4="All",B13=Search!$C$4),OR(Search!$C$5="",Search!$C$5="All",C13=Search!$C$5),OR(Search!$C$6="",Search!$C$6="All",D13=Search!$C$6),OR(Search!$C$7="",ISNUMBER(SEARCH(Search!$C$7,D13&" "&E13&" "&F13&" "&G13&" "&H13&" "&J13))),OR(Search!$C$8="",ISNUMBER(SEARCH(Search!$C$8,G13)))),1,0) -> 1 | M13: =M12+L13 -> 12
A14: 13 | B14: Hi-Gloss Lamination, Inc. | C14: Lamination / Finishing Service | D14: Japan Blister (2 Layers) | H14: per sq. inch | I14: 0.008 | J14: Min. P0.80/sheet; Min. P500.00/job | K14: Sep 2018 | L14: =IF(AND(OR(Search!$C$4="",Search!$C$4="All",B14=Search!$C$4),OR(Search!$C$5="",Search!$C$5="All",C14=Search!$C$5),OR(Search!$C$6="",Search!$C$6="All",D14=Search!$C$6),OR(Search!$C$7="",ISNUMBER(SEARCH(Search!$C$7,D14&" "&E14&" "&F14&" "&G14&" "&H14&" "&J14))),OR(Search!$C$8="",ISNUMBER(SEARCH(Search!$C$8,G14)))),1,0) -> 1 | M14: =M13+L14 -> 13
A15: 14 | B15: Hi-Gloss Lamination, Inc. | C15: Lamination / Finishing Service | D15: Hologram Lamination | G15: Width 12" | H15: per sq. inch | I15: 0.025 | J15: Min. P2.00/sheet; Min. P1,000.00/job | K15: Sep 2018 | L15: =IF(AND(OR(Search!$C$4="",Search!$C$4="All",B15=Search!$C$4),OR(Search!$C$5="",Search!$C$5="All",C15=Search!$C$5),OR(Search!$C$6="",Search!$C$6="All",D15=Search!$C$6),OR(Search!$C$7="",ISNUMBER(SEARCH(Search!$C$7,D15&" "&E15&" "&F15&" "&G15&" "&H15&" "&J15))),OR(Search!$C$8="",ISNUMBER(SEARCH(Search!$C$8,G15)))),1,0) -> 1 | M15: =M14+L15 -> 14
A16: 15 | B16: Hi-Gloss Lamination, Inc. | C16: Lamination / Finishing Service | D16: Wax Lamination | H16: per sq. inch | I16: 0.0035 | J16: Min. P1.00/sheet; Min. P1,000.00/job | K16: Sep 2018 | L16: =IF(AND(OR(Search!$C$4="",Search!$C$4="All",B16=Search!$C$4),OR(Search!$C$5="",Search!$C$5="All",C16=Search!$C$5),OR(Search!$C$6="",Search!$C$6="All",D16=Search!$C$6),OR(Search!$C$7="",ISNUMBER(SEARCH(Search!$C$7,D16&" "&E16&" "&F16&" "&G16&" "&H16&" "&J16))),OR(Search!$C$8="",ISNUMBER(SEARCH(Search!$C$8,G16)))),1,0) -> 1 | M16: =M15+L16 -> 15
A17: 16 | B17: Hi-Gloss Lamination, Inc. | C17: Lamination / Finishing Service | D17: Velvet Soft Touch | G17: Width 12.5", 18.75", 24" | H17: per sq. inch | I17: 0.035 | J17: Min. P2.00/sheet; Min. P1,500.00/job | K17: Sep 2018 | L17: =IF(AND(OR(Search!$C$4="",Search!$C$4="All",B17=Search!$C$4),OR(Search!$C$5="",Search!$C$5="All",C17=Search!$C$5),OR(Search!$C$6="",Search!$C$6="All",D17=Search!$C$6),OR(Search!$C$7="",ISNUMBER(SEARCH(Search!$C$7,D17&" "&E17&" "&F17&" "&G17&" "&H17&" "&J17))),OR(Search!$C$8="",ISNUMBER(SEARCH(Search!$C$8,G17)))),1,0) -> 1 | M17: =M16+L17 -> 16
A18: 17 | B18: Hi-Gloss Lamination, Inc. | C18: Lamination / Finishing Service | D18: Metallized Lamination | E18: Silver | G18: Width 31" or 25" | H18: per sq. inch | I18: 0.016 | J18: Min. P2,000.00/job | K18: Sep 2018 | L18: =IF(AND(OR(Search!$C$4="",Search!$C$4="All",B18=Search!$C$4),OR(Search!$C$5="",Search!$C$5="All",C18=Search!$C$5),OR(Search!$C$6="",Search!$C$6="All",D18=Search!$C$6),OR(Search!$C$7="",ISNUMBER(SEARCH(Search!$C$7,D18&" "&E18&" "&F18&" "&G18&" "&H18&" "&J18))),OR(Search!$C$8="",ISNUMBER(SEARCH(Search!$C$8,G18)))),1,0) -> 1 | M18: =M17+L18 -> 17
A19: 18 | B19: Hi-Gloss Lamination, Inc. | C19: Lamination / Finishing Service | D19: Metallized Lamination | E19: Gold | G19: Width 31" or 25" | H19: per sq. inch | I19: 0.024 | J19: Min. P2,000.00/job | K19: Sep 2018 | L19: =IF(AND(OR(Search!$C$4="",Search!$C$4="All",B19=Search!$C$4),OR(Search!$C$5="",Search!$C$5="All",C19=Search!$C$5),OR(Search!$C$6="",Search!$C$6="All",D19=Search!$C$6),OR(Search!$C$7="",ISNUMBER(SEARCH(Search!$C$7,D19&" "&E19&" "&F19&" "&G19&" "&H19&" "&J19))),OR(Search!$C$8="",ISNUMBER(SEARCH(Search!$C$8,G19)))),1,0) -> 1 | M19: =M18+L19 -> 18
A20: 19 | B20: Hi-Gloss Lamination, Inc. | C20: Lamination / Finishing Service | D20: Metallized Lamination | E20: Red / Green | G20: Width 31" | H20: per sq. inch | I20: 0.024 | J20: Min. P2,000.00/job | K20: Sep 2018 | L20: =IF(AND(OR(Search!$C$4="",Search!$C$4="All",B20=Search!$C$4),OR(Search!$C$5="",Search!$C$5="All",C20=Search!$C$5),OR(Search!$C$6="",Search!$C$6="All",D20=Search!$C$6),OR(Search!$C$7="",ISNUMBER(SEARCH(Search!$C$7,D20&" "&E20&" "&F20&" "&G20&" "&H20&" "&J20))),OR(Search!$C$8="",ISNUMBER(SEARCH(Search!$C$8,G20)))),1,0) -> 1 | M20: =M19+L20 -> 19
A21: 20 | B21: Hi-Gloss Lamination, Inc. | C21: Lamination / Finishing Service | D21: Spot UV Blanket Charge (glue lap/expiry date) | E21: Small | G21: 23" x 28" | H21: per job | I21: 1500 | K21: Sep 2018 | L21: =IF(AND(OR(Search!$C$4="",Search!$C$4="All",B21=Search!$C$4),OR(Search!$C$5="",Search!$C$5="All",C21=Search!$C$5),OR(Search!$C$6="",Search!$C$6="All",D21=Search!$C$6),OR(Search!$C$7="",ISNUMBER(SEARCH(Search!$C$7,D21&" "&E21&" "&F21&" "&G21&" "&H21&" "&J21))),OR(Search!$C$8="",ISNUMBER(SEARCH(Search!$C$8,G21)))),1,0) -> 1 | M21: =M20+L21 -> 20
A22: 21 | B22: Hi-Gloss Lamination, Inc. | C22: Lamination / Finishing Service | D22: Spot UV Blanket Charge (glue lap/expiry date) | E22: Big | G22: 34" x 40" | H22: per job | I22: 2000 | K22: Sep 2018 | L22: =IF(AND(OR(Search!$C$4="",Search!$C$4="All",B22=Search!$C$4),OR(Search!$C$5="",Search!$C$5="All",C22=Search!$C$5),OR(Search!$C$6="",Search!$C$6="All",D22=Search!$C$6),OR(Search!$C$7="",ISNUMBER(SEARCH(Search!$C$7,D22&" "&E22&" "&F22&" "&G22&" "&H22&" "&J22))),OR(Search!$C$8="",ISNUMBER(SEARCH(Search!$C$8,G22)))),1,0) -> 1 | M22: =M21+L22 -> 21
A23: 22 | B23: Hi-Gloss Lamination, Inc. | C23: Lamination / Finishing Service | D23: 3D Spot Exposure Charge | E23: Small / medium size | G23: below 20" x 28" | H23: per design | I23: 800 | J23: Requires positive emulsion up film | K23: Sep 2018 | L23: =IF(AND(OR(Search!$C$4="",Search!$C$4="All",B23=Search!$C$4),OR(Search!$C$5="",Search!$C$5="All",C23=Search!$C$5),OR(Search!$C$6="",Search!$C$6="All",D23=Search!$C$6),OR(Search!$C$7="",ISNUMBER(SEARCH(Search!$C$7,D23&" "&E23&" "&F23&" "&G23&" "&H23&" "&J23))),OR(Search!$C$8="",ISNUMBER(SEARCH(Search!$C$8,G23)))),1,0) -> 1 | M23: =M22+L23 -> 22
A24: 23 | B24: Hi-Gloss Lamination, Inc. | C24: Lamination / Finishing Service | D24: 3D Spot Exposure Charge | E24: Large size | G24: 20" x 28" and above | H24: per design | I24: 1200 | J24: Requires positive emulsion up film | K24: Sep 2018 | L24: =IF(AND(OR(Search!$C$4="",Search!$C$4="All",B24=Search!$C$4),OR(Search!$C$5="",Search!$C$5="All",C24=Search!$C$5),OR(Search!$C$6="",Search!$C$6="All",D24=Search!$C$6),OR(Search!$C$7="",ISNUMBER(SEARCH(Search!$C$7,D24&" "&E24&" "&F24&" "&G24&" "&H24&" "&J24))),OR(Search!$C$8="",ISNUMBER(SEARCH(Search!$C$8,G24)))),1,0) -> 1 | M24: =M23+L24 -> 23
A25: 24 | B25: Hi-Gloss Lamination, Inc. | C25: Lamination / Finishing Service | D25: 3D Spot - Digital Jobs | E25: Minimum charge | H25: per job | I25: 1500 | K25: Sep 2018 | L25: =IF(AND(OR(Search!$C$4="",Search!$C$4="All",B25=Search!$C$4),OR(Search!$C$5="",Search!$C$5="All",C25=Search!$C$5),OR(Search!$C$6="",Search!$C$6="All",D25=Search!$C$6),OR(Search!$C$7="",ISNUMBER(SEARCH(Search!$C$7,D25&" "&E25&" "&F25&" "&G25&" "&H25&" "&J25))),OR(Search!$C$8="",ISNUMBER(SEARCH(Search!$C$8,G25)))),1,0) -> 1 | M25: =M24+L25 -> 24
A26: 25 | B26: Commerce Asia, Inc. | C26: Lamination Film | D26: Thermal OPP Film (for offset) | E26: Glossy/25, 58mm core | F26: 23110-0305-1000-58 | G26: 305mm (12 in) x 1000M | H26: roll | I26: 2716 | J26: SRP P4,850.00 less 44% discount | K26: Jul 20, 2026 | L26: =IF(AND(OR(Search!$C$4="",Search!$C$4="All",B26=Search!$C$4),OR(Search!$C$5="",Search!$C$5="All",C26=Search!$C$5),OR(Search!$C$6="",Search!$C$6="All",D26=Search!$C$6),OR(Search!$C$7="",ISNUMBER(SEARCH(Search!$C$7,D26&" "&E26&" "&F26&" "&G26&" "&H26&" "&J26))),OR(Search!$C$8="",ISNUMBER(SEARCH(Search!$C$8,G26)))),1,0) -> 1 | M26: =M25+L26 -> 25
A27: 26 | B27: Commerce Asia, Inc. | C27: Lamination Film | D27: Thermal OPP Film (for offset) | E27: Glossy/25, 58mm core | F27: 23110-0320-1000-58 | G27: 320mm (12.6 in) x 1000M | H27: roll | I27: 2861.6 | J27: SRP P5,110.00 less 44% discount | K27: Jul 20, 2026 | L27: =IF(AND(OR(Search!$C$4="",Search!$C$4="All",B27=Search!$C$4),OR(Search!$C$5="",Search!$C$5="All",C27=Search!$C$5),OR(Search!$C$6="",Search!$C$6="All",D27=Search!$C$6),OR(Search!$C$7="",ISNUMBER(SEARCH(Search!$C$7,D27&" "&E27&" "&F27&" "&G27&" "&H27&" "&J27))),OR(Search!$C$8="",ISNUMBER(SEARCH(Search!$C$8,G27)))),1,0) -> 1 | M27: =M26+L27 -> 26
A28: 27 | B28: Commerce Asia, Inc. | C28: Lamination Film | D28: Thermal OPP Film (for offset) | E28: Glossy/25, 58mm core | F28: 23110-0330-1000-58 | G28: 330mm (13 in) x 1000M | H28: roll | I28: 2940 | J28: SRP P5,250.00 less 44% discount | K28: Jul 20, 2026 | L28: =IF(AND(OR(Search!$C$4="",Search!$C$4="All",B28=Search!$C$4),OR(Search!$C$5="",Search!$C$5="All",C28=Search!$C$5),OR(Search!$C$6="",Search!$C$6="All",D28=Search!$C$6),OR(Search!$C$7="",ISNUMBER(SEARCH(Search!$C$7,D28&" "&E28&" "&F28&" "&G28&" "&H28&" "&J28))),OR(Search!$C$8="",ISNUMBER(SEARCH(Search!$C$8,G28)))),1,0) -> 1 | M28: =M27+L28 -> 27
A29: 28 | B29: Commerce Asia, Inc. | C29: Lamination Film | D29: Thermal OPP Film (for offset) | E29: Glossy/25, 58mm core | F29: 23110-0360-1000-58 | G29: 360mm (14.17 in) x 1000M | H29: roll | I29: 3203.2 | J29: SRP P5,720.00 less 44% discount | K29: Jul 20, 2026 | L29: =IF(AND(OR(Search!$C$4="",Search!$C$4="All",B29=Search!$C$4),OR(Search!$C$5="",Search!$C$5="All",C29=Search!$C$5),OR(Search!$C$6="",Search!$C$6="All",D29=Search!$C$6),OR(Search!$C$7="",ISNUMBER(SEARCH(Search!$C$7,D29&" "&E29&" "&F29&" "&G29&" "&H29&" "&J29))),OR(Search!$C$8="",ISNUMBER(SEARCH(Search!$C$8,G29)))),1,0) -> 1 | M29: =M28+L29 -> 28
A30: 29 | B30: Commerce Asia, Inc. | C30: Lamination Film | D30: Thermal OPP Film (for offset) | E30: Glossy/25, 58mm core | F30: 23110-0385-1000-58 | G30: 385mm (15.16 in) x 1000M | H30: roll | I30: 3444 | J30: SRP P6,150.00 less 44% discount | K30: Jul 20, 2026 | L30: =IF(AND(OR(Search!$C$4="",Search!$C$4="All",B30=Search!$C$4),OR(Search!$C$5="",Search!$C$5="All",C30=Search!$C$5),OR(Search!$C$6="",Search!$C$6="All",D30=Search!$C$6),OR(Search!$C$7="",ISNUMBER(SEARCH(Search!$C$7,D30&" "&E30&" "&F30&" "&G30&" "&H30&" "&J30))),OR(Search!$C$8="",ISNUMBER(SEARCH(Search!$C$8,G30)))),1,0) -> 1 | M30: =M29+L30 -> 29
A31: 30 | B31: Commerce Asia, Inc. | C31: Lamination Film | D31: Thermal OPP Film (for offset) | E31: Glossy/25, 58mm core | F31: 23110-0410-1000-58 | G31: 410mm (16.14 in) x 1000M | H31: roll | I31: 3651.2 | J31: SRP P6,520.00 less 44% discount | K31: Jul 20, 2026 | L31: =IF(AND(OR(Search!$C$4="",Search!$C$4="All",B31=Search!$C$4),OR(Search!$C$5="",Search!$C$5="All",C31=Search!$C$5),OR(Search!$C$6="",Search!$C$6="All",D31=Search!$C$6),OR(Search!$C$7="",ISNUMBER(SEARCH(Search!$C$7,D31&" "&E31&" "&F31&" "&G31&" "&H31&" "&J31))),OR(Search!$C$8="",ISNUMBER(SEARCH(Search!$C$8,G31)))),1,0) -> 1 | M31: =M30+L31 -> 30
A32: 31 | B32: Commerce Asia, Inc. | C32: Lamination Film | D32: Thermal OPP Film (for offset) | E32: Glossy/25, 58mm core | F32: 23110-0432-1000-58 | G32: 432mm (17 in) x 1000M | H32: roll | I32: 3864 | J32: SRP P6,900.00 less 44% discount | K32: Jul 20, 2026 | L32: =IF(AND(OR(Search!$C$4="",Search!$C$4="All",B32=Search!$C$4),OR(Search!$C$5="",Search!$C$5="All",C32=Search!$C$5),OR(Search!$C$6="",Search!$C$6="All",D32=Search!$C$6),OR(Search!$C$7="",ISNUMBER(SEARCH(Search!$C$7,D32&" "&E32&" "&F32&" "&G32&" "&H32&" "&J32))),OR(Search!$C$8="",ISNUMBER(SEARCH(Search!$C$8,G32)))),1,0) -> 1 | M32: =M31+L32 -> 31
A33: 32 | B33: Commerce Asia, Inc. | C33: Lamination Film | D33: Thermal OPP Film (for offset) | E33: Glossy/25, 58mm core | F33: 23110-0460-1000-58 | G33: 460mm (18.11 in) x 1000M | H33: roll | I33: 4088 | J33: SRP P7,300.00 less 44% discount | K33: Jul 20, 2026 | L33: =IF(AND(OR(Search!$C$4="",Search!$C$4="All",B33=Search!$C$4),OR(Search!$C$5="",Search!$C$5="All",C33=Search!$C$5),OR(Search!$C$6="",Search!$C$6="All",D33=Search!$C$6),OR(Search!$C$7="",ISNUMBER(SEARCH(Search!$C$7,D33&" "&E33&" "&F33&" "&G33&" "&H33&" "&J33))),OR(Search!$C$8="",ISNUMBER(SEARCH(Search!$C$8,G33)))),1,0) -> 1 | M33: =M32+L33 -> 32
A34: 33 | B34: Commerce Asia, Inc. | C34: Lamination Film | D34: Thermal OPP Film (for offset) | E34: Glossy/25, 58mm core | F34: 23110-0485-1000-58 | G34: 485mm (19.09 in) x 1000M | H34: roll | I34: 4340 | J34: SRP P7,750.00 less 44% discount | K34: Jul 20, 2026 | L34: =IF(AND(OR(Search!$C$4="",Search!$C$4="All",B34=Search!$C$4),OR(Search!$C$5="",Search!$C$5="All",C34=Search!$C$5),OR(Search!$C$6="",Search!$C$6="All",D34=Search!$C$6),OR(Search!$C$7="",ISNUMBER(SEARCH(Search!$C$7,D34&" "&E34&" "&F34&" "&G34&" "&H34&" "&J34))),OR(Search!$C$8="",ISNUMBER(SEARCH(Search!$C$8,G34)))),1,0) -> 1 | M34: =M33+L34 -> 33
A35: 34 | B35: Commerce Asia, Inc. | C35: Lamination Film | D35: Thermal OPP Film (for offset) | E35: Glossy/25, 58mm core | F35: 23110-0635-1000-58 | G35: 635mm (25 in) x 1000M | H35: roll | I35: 5656 | J35: SRP P10,100.00 less 44% discount | K35: Jul 20, 2026 | L35: =IF(AND(OR(Search!$C$4="",Search!$C$4="All",B35=Search!$C$4),OR(Search!$C$5="",Search!$C$5="All",C35=Search!$C$5),OR(Search!$C$6="",Search!$C$6="All",D35=Search!$C$6),OR(Search!$C$7="",ISNUMBER(SEARCH(Search!$C$7,D35&" "&E35&" "&F35&" "&G35&" "&H35&" "&J35))),OR(Search!$C$8="",ISNUMBER(SEARCH(Search!$C$8,G35)))),1,0) -> 1 | M35: =M34+L35 -> 34
A36: 35 | B36: Commerce Asia, Inc. | C36: Lamination Film | D36: Thermal OPP Film (for offset) | E36: Matt/28, 58mm core | F36: 23111-0305-1000-58 | G36: 305mm (12 in) x 1000M | H36: roll | I36: 3528 | J36: SRP P6,300.00 less 44% discount | K36: Jul 20, 2026 | L36: =IF(AND(OR(Search!$C$4="",Search!$C$4="All",B36=Search!$C$4),OR(Search!$C$5="",Search!$C$5="All",C36=Search!$C$5),OR(Search!$C$6="",Search!$C$6="All",D36=Search!$C$6),OR(Search!$C$7="",ISNUMBER(SEARCH(Search!$C$7,D36&" "&E36&" "&F36&" "&G36&" "&H36&" "&J36))),OR(Search!$C$8="",ISNUMBER(SEARCH(Search!$C$8,G36)))),1,0) -> 1 | M36: =M35+L36 -> 35
A37: 36 | B37: Commerce Asia, Inc. | C37: Lamination Film | D37: Thermal OPP Film (for offset) | E37: Matt/28, 58mm core | F37: 23111-0320-1000-58 | G37: 320mm (12.6 in) x 1000M | H37: roll | I37: 3690.4 | J37: SRP P6,590.00 less 44% discount | K37: Jul 20, 2026 | L37: =IF(AND(OR(Search!$C$4="",Search!$C$4="All",B37=Search!$C$4),OR(Search!$C$5="",Search!$C$5="All",C37=Search!$C$5),OR(Search!$C$6="",Search!$C$6="All",D37=Search!$C$6),OR(Search!$C$7="",ISNUMBER(SEARCH(Search!$C$7,D37&" "&E37&" "&F37&" "&G37&" "&H37&" "&J37))),OR(Search!$C$8="",ISNUMBER(SEARCH(Search!$C$8,G37)))),1,0) -> 1 | M37: =M36+L37 -> 36
... A52: 51 | B52: Commerce Asia, Inc. | C52: Lamination Film | D52: Thermal PET Film (offset & digital) | E52: Matt/32-G, 58mm core | F52: 21103-0457-150-G58 | G52: 457mm (18 in) x 150M | H52: roll | I52: 4425 | J52: SRP P5,900.00 less 25% discount | K52: Jul 20, 2026 | L52: =IF(AND(OR(Search!$C$4="",Search!$C$4="All",B52=Search!$C$4),OR(Search!$C$5="",Search!$C$5="All",C52=Search!$C$5),OR(Search!$C$6="",Search!$C$6="All",D52=Search!$C$6),OR(Search!$C$7="",ISNUMBER(SEARCH(Search!$C$7,D52&" "&E52&" "&F52&" "&G52&" "&H52&" "&J52))),OR(Search!$C$8="",ISNUMBER(SEARCH(Search!$C$8,G52)))),1,0) -> 1 | M52: =M51+L52 -> 51
A53: 52 | B53: Crosspoint Paper (Silang, Cavite) | C53: Newsprint | D53: Newsprint | F53: 52 gsm | G53: 24 x 36 | H53: ream | I53: 730 | K53: 2025 | L53: =IF(AND(OR(Search!$C$4="",Search!$C$4="All",B53=Search!$C$4),OR(Search!$C$5="",Search!$C$5="All",C53=Search!$C$5),OR(Search!$C$6="",Search!$C$6="All",D53=Search!$C$6),OR(Search!$C$7="",ISNUMBER(SEARCH(Search!$C$7,D53&" "&E53&" "&F53&" "&G53&" "&H53&" "&J53))),OR(Search!$C$8="",ISNUMBER(SEARCH(Search!$C$8,G53)))),1,0) -> 1 | M53: =M52+L53 -> 52
A54: 53 | B54: Crosspoint Paper (Silang, Cavite) | C54: Newsprint | D54: Newsprint | F54: 52 gsm | G54: 34 x 28 | H54: ream | I54: 804.35 | K54: 2025 | L54: =IF(AND(OR(Search!$C$4="",Search!$C$4="All",B54=Search!$C$4),OR(Search!$C$5="",Search!$C$5="All",C54=Search!$C$5),OR(Search!$C$6="",Search!$C$6="All",D54=Search!$C$6),OR(Search!$C$7="",ISNUMBER(SEARCH(Search!$C$7,D54&" "&E54&" "&F54&" "&G54&" "&H54&" "&J54))),OR(Search!$C$8="",ISNUMBER(SEARCH(Search!$C$8,G54)))),1,0) -> 1 | M54: =M53+L54 -> 53
...

Sheet Suppliers
A1: Supplier | B1: Price List Date | C1: No. of Items | D1: Address | E1: Contact Person | F1: Phone / Mobile | G1: Email / Website | H1: Remarks | I1: Source File
A2: Hi-Gloss Lamination, Inc. | B2: Sep 2018 | C2: =COUNTIF('Price List'!$B$2:$B$1352,A2) -> 24 | D2: 289 Dayao cor. Buendia St., Balut, Tondo, Manila | F2: Tel (02) 523-1915 / (02) 522-2930; Telefax (02) 523-1957; Smart 0920-961-8042; Sun 0942-258-2109; Globe 0966-670-2532 | G2: hi.gloss@yahoo.com; www.higlosslamination.com | H2: 3D Spot requires positive emulsion up film. Prices may change without prior notice. List is dated 2018 - confirm current rates. | I2: Hi-Gloss price list (photo)
A3: Commerce Asia, Inc. | B3: Jul 20, 2026 | C3: =COUNTIF('Price List'!$B$2:$B$1352,A3) -> 27 | E3: Antonio N. Gavarra | F3: (632) 8726-4030 loc. 307; Mobile/Viber 0917-713-3467 | H3: Price shown = discounted price (SRP less discount). | I3: COMMASIA_10.2026.pdf
A4: Crosspoint Paper (Silang, Cavite) | B4: 2025 | C4: =COUNTIF('Price List'!$B$2:$B$1352,A4) -> 30 | D4: Silang, Cavite | H4: Newsprint and book paper per ream. | I4: 2025_CROSSPOINT_PAPER_SILANG_CAVITE.docx
A5: NAPPCO (Nov 7, 2023 list) | B5: Nov 7, 2023 | C5: =COUNTIF('Price List'!$B$2:$B$1352,A5) -> 151 | H5: Older list - superseded by April list where items overlap. | I5: NAPPCO price list (image)
A6: NAPPCO (April list - latest) | B6: April (year not shown) | C6: =COUNTIF('Price List'!$B$2:$B$1352,A6) -> 149 | H6: Marked 'internal document, prices indicative only and may change anytime'. Volume discounts via sales head. Handwritten updates included and flagged in Notes. | I6: NAPPCO price list (photo, with handwritten updates)
A7: Star Paper Corp. (Luzon) | B7: May 26, 2026 | C7: =COUNTIF('Price List'!$B$2:$B$1352,A7) -> 407 | E7: Troy (North 1); Jay (North 2); Anthony (South) | F7: Office 0939-913-0347 / 0998-955-4681; Troy 0908-894-7714; Jay 0998-996-6289; Anthony 0928-550-5419 | H7: Dense scanned list - rows flagged 'verify' in Notes were hard to read; confirm with supplier. | I7: Star Paper Luzon price list (scan)
A8: IFEX Philippines (Manila Printer Pricelist) | B8: Q2 2026 (valid to Jun 30, 2026) | C8: =COUNTIF('Price List'!$B$2:$B$1352,A8) -> 283 | D8: 46 Joy Street, Grace Village, Quezon City 1115 (pick-up & delivery) | F8: Trunk line 8364-6041 to 49, locals 516-525 | H8: Unit price per sheet. *New items; **Until supplies last. | I8: IFEX_2026_Manila_Printer_Official_Pricelist_Q2_2026.pdf
A9: IFEX Philippines (Retail SRP List) | B9: Apr 30, 2026 | C9: =COUNTIF('Price List'!$B$2:$B$1352,A9) -> 259 | E9: Angelina F. Singh (Luzon Sales Coordinator); noted by Jeffrey Miranda (Luzon Sales Supervisor) | F9: +632 364-6041 to 49 loc. 524; Viber 0907-333-3333 | G9: luzonnorth@ifex.com.ph | H9: Prices are SRP. | I9: IFEX_Price_List_Effective_043026.pdf
A10: IPLMI (Calamba, Laguna) | B10: 2024 (brochure) | C10: =COUNTIF('Price List'!$B$2:$B$1352,A10) -> 21 | D10: Lot C3-3C Carmelray Industrial Park 2, Km. 54 National Highway, Calamba City, Laguna 4027; 2560 Marcelita Bldg., National Highway, Brgy. Real, Calamba City | E10: Vinizza A. Farenas (Sales Executive); Julie Ann Tipon-tipon (Sales Coordinator) | F10: 0908-898-7777; 0920-961-3285; (049) 545-2885 | G10: sales@iplmi.com; admin@iplmi.net | H10: Brochure only - no prices. ISO 9001:2015, ISO 14001:2015, ISO 45001:2018. Request quotation. | I10: IPLMI_Company_Profile_and_Brochure_2024.pdf
A12: Legend
A13: Yellow cells on the Search tab are the only cells to edit (dropdowns / keywords).
A14: Blue prices on the Price List tab are hardcoded values taken from each supplier's list; add new rows at the bottom of the table to extend it.
A15: Notes column flags 'verify' where the source scan was hard to read, and 'Handwritten update' where the supplier list had pen corrections.

Sheet Lists
A1: Suppliers | B1: Categories | C1: All Items | D1: Category (for item list) | E1: Item (by category)
A2: All | B2: All | C2: All | D2: Board / Specialty | E2: Chipboard
A3: Hi-Gloss Lamination, Inc. | B3: Board / Specialty | C3: 3D Dyna Spot (Pattern) | D3: Board / Specialty | E3: Glassine
A4: Commerce Asia, Inc. | B4: Bond Paper | C4: 3D Glitters (Multi-Colored) | D4: Board / Specialty | E4: Illustration Board
A5: Crosspoint Paper (Silang, Cavite) | B5: Book Paper | C5: 3D Spot (Heavy Duty) | D5: Board / Specialty | E5: Oslo Paper BTO
A6: NAPPCO (Nov 7, 2023 list) | B6: Bookcover Material | C6: 3D Spot (Matt) | D6: Board / Specialty | E6: Parchment
A7: NAPPCO (April list - latest) | B7: Bristol / Vellum | C7: 3D Spot (Ordinary / Semi-Heavy Duty) | D7: Board / Specialty | E7: Pasteboard
A8: Star Paper Corp. (Luzon) | B8: Carbonless Paper | C8: 3D Spot - Digital Jobs | D8: Board / Specialty | E8: Tissue
A9: IFEX Philippines (Manila Printer Pricelist) | B9: Cast Coated (Kromkote) | C9: 3D Spot Exposure Charge | D9: Bond Paper | E9: BE 49gsm
A10: IFEX Philippines (Retail SRP List) | B10: Coated Paper (C1S) | C10: 3D Stone Finish | D10: Bond Paper | E10: Bond Paper
A11: IPLMI (Calamba, Laguna) | B11: Coated Paper (C2S/Matte) | C11: 5D Spot Hologram (3 Designs) | D11: Bond Paper | E11: Bond White (Book Paper Quality)
B12: Coated Paper (PE Coated) | C12: Arco Smooth | D12: Bond Paper | E12: Colored Bond
B13: Colored Paper | C13: Artelibris | D13: Bond Paper | E13: JN Book 45g
B14: Digital Substrate | C14: Assorted Colored Paper | D14: Bond Paper | E14: JN Book 50g
B15: Envelopes | C15: Astro | D15: Bond Paper | E15: JN Book 55/60g
B16: Fine Arts Supplies | C16: Astro Premium Envelope A2 | D16: Bond Paper | E16: MT 51gsm
B17: Glue / Adhesive | C17: Astro Premium Envelope A6 | D17: Bond Paper | E17: MT 54gsm
B18: Greaseproof Paper | C18: Astro Premium Envelope A9 | D18: Bond Paper | E18: MT 58gsm
B19: Kraft Paper | C19: BE 49gsm | D19: Bond Paper | E19: MT 68gsm
B20: Lamination / Finishing Service | C20: Blackgold | D20: Bond Paper | E20: Onion Skin TK042 (by 2 reams w/ paper wrap)
B21: Lamination Film | C21: Bleach Kraft | D21: Bond Paper | E21: Onion Skin TK042 (w/ plastic)
B22: Newsprint | C22: Blossoms | D22: Bond Paper | E22: TE 48gsm
B23: Office / Copy Paper | C23: Bond Paper | D23: Bond Paper | E23: TE 51gsm
... B32: Sticker Paper | C32: Book Paper | D32: Book Paper | E32: Book Paper
C33: Book Paper (box x 5 reams) | D33: Book Paper | E33: Book Paper (box x 5 reams)
C34: Bookbinding Board - DHBJ/DHB | D34: Book Paper | E34: Cream Book
C35: Bookbinding Board - SVB | D35: Bookcover Material | E35: Artelibris
C36: Boxboard TVB (BLE) | D36: Bookcover Material | E36: Buffalo Skin
C37: Bristol / Vellum - Imported | D37: Bookcover Material | E37: Starlin B-Cvr
